Workbook

Sheet Dashboard
B16: ERROR DISTRIBUTION
B18: Issue | F18: Error Count
B19: Invalid Birth Year | F19: =Summary!B9 -> 2
B22: Invalid Marital Status | F22: =Summary!B11 -> 4
B25: Invalid Income | F25: =Summary!B12 -> 24

Sheet Summary
A1: Customer Data Quality Audit Summary
A2: Dataset Overview
A3: Metric | B3: Value
A4: Total Records | B4: =COUNTA(Data_Audit!A:A)-1 -> 2240
A6: Data Quality Issues
A7: Metric | B7: Value | C7: Error %
A8: Duplicate IDs | B8: =COUNTIF(Data_Audit!AD:AD,"Duplicate") -> 0 | C8: =$B8/$B$4 -> 0
A9: Invalid Birth Year | B9: =COUNTIF(Data_Audit!AE:AE,"Invalid") -> 2 | C9: =$B9/$B$4 -> 0.00089285714
A10: Invalid Education Category | B10: =COUNTIF(Data_Audit!AF:AF,"Invalid") -> 0 | C10: =$B10/$B$4 -> 0
A11: Invalid Marital Status | B11: =COUNTIF(Data_Audit!AG:AG,"Invalid") -> 4 | C11: =$B11/$B$4 -> 0.0017857143
A12: Invalid Income | B12: =COUNTIF(Data_Audit!AH:AH,"Invalid") -> 24 | C12: =$B12/$B$4 -> 0.010714286
A13: Invalid Kidhome | B13: =COUNTIF(Data_Audit!AI:AI,"Invalid") -> 0 | C13: =$B13/$B$4 -> 0
A14: Invalid Teenhome | B14: =COUNTIF(Data_Audit!AJ:AJ,"Invalid") -> 0 | C14: =$B14/$B$4 -> 0
A15: Invalid Customer Date | B15: =COUNTIF(Data_Audit!AK:AK,"Invalid") -> 0 | C15: =$B15/$B$4 -> 0
A16: Invalid Recency | B16: =COUNTIF(Data_Audit!AL:AL,"Invalid") -> 0 | C16: =$B16/$B$4 -> 0
A17: Invalid Product Spending | B17: =COUNTIF(Data_Audit!AM:AM,"Invalid") -> 0 | C17: =$B17/$B$4 -> 0
A18: Invalid Purchase Counts | B18: =COUNTIF(Data_Audit!AN:AN,"Invalid") -> 0 | C18: =$B18/$B$4 -> 0
A19: Invalid Campaign Values | B19: =COUNTIF(Data_Audit!AO:AO,"Invalid") -> 0 | C19: =$B19/$B$4 -> 0
A20: Invalid Complaint Values | B20: =COUNTIF(Data_Audit!AP:AP,"Invalid") -> 0 | C20: =$B20/$B$4 -> 0
A21: Invalid Z_CostContact | B21: =COUNTIF(Data_Audit!AQ:AQ,"Invalid") -> 0 | C21: =$B21/$B$4 -> 0
A22: Invalid Z_Revenue | B22: =COUNTIF(Data_Audit!AR:AR,"Invalid") -> 0 | C22: =$B22/$B$4 -> 0
A23: Invalid Response | B23: =COUNTIF(Data_Audit!AS:AS,"Invalid") -> 0 | C23: =$B23/$B$4 -> 0
A25: Data Quality KPIs
A26: Metric | B26: Value
A27: Total Errors | B27: =SUM(B8:B23) -> 30
A28: Data Quality Score | B28: =1-(B27/B4) -> 0.98660714

Sheet Data_Audit
A1: ID | B1: Year_Birth | C1: Education | D1: Marital_Status | E1: Income | F1: Kidhome | G1: Teenhome | H1: Dt_Customer | I1: Recency | J1: MntWines | K1: MntFruits | L1: MntMeatProducts | M1: MntFishProducts | N1: MntSweetProducts | O1: MntGoldProds | P1: NumDealsPurchases | Q1: NumWebPurchases | R1: NumCatalogPurchases | S1: NumStorePurchases | T1: NumWebVisitsMonth | U1: AcceptedCmp3 | V1: AcceptedCmp4 | W1: AcceptedCmp5 | X1: AcceptedCmp1 | Y1: AcceptedCmp2 | Z1: Complain | AA1: Z_CostContact | AB1: Z_Revenue | AC1: Response | AD1: Duplicate_ID_Check | AE1: Birth_Year_Check | AF1: Education_Category_Check | AG1: Marital_Status_Check | AH1: Income_Validity_Check | AI1: Kidhome_Range_Check | AJ1: Teenhome_Range_Check | AK1: Customer_Date_Validity_Check | AL1: Recency_Range_Check | AM1: Product_Spending_Check | AN1: Purchase_Count_Validity_Check | AO1: Campaign_Check | AP1: Complaint_Binary_Check | AQ1: Z_CostContact_Constant_Check | AR1: Z_Revenue_Constant_Check | AS1: Response_Binary_Check
A2: 5524 | B2: 1957 | C2: Graduation | D2: Single | E2: 58138 | F2: 0 | G2: 0 | H2: 41156 | I2: 58 | J2: 635 | K2: 88 | L2: 546 | M2: 172 | N2: 88 | O2: 88 | P2: 3 | Q2: 8 | R2: 10 | S2: 4 | T2: 7 | U2: 0 | V2: 0 | W2: 0 | X2: 0 | Y2: 0 | Z2: 0 | AA2: 3 | AB2: 11 | AC2: 1 | AD2: =IF(COUNTIF(A:A,A2)>1,"Duplicate","Ok") -> Ok | AE2: =IF(AND(Audit_Data[[#This Row],[Year_Birth]]>=1900,Audit_Data[[#This Row],[Year_Birth]]<=2010),"OK","Invalid") -> OK | AF2: =IF(OR(C2="Graduation",C2="phD",C2="Master",C2="Basic",C2="2n Cycle"),"Valid","Invalid") -> Valid | AG2: =IF(OR(D2="Single",D2="Married",D2="Divorced",D2="Together",D2="Widow",D2="Alone"),"Valid","Invalid") -> Valid | AH2: =IF(AND(ISNUMBER(E2),E2<>""),"Valid","Invalid") -> Valid | AI2: =IF(AND(F2>=0,F2<=2),"Valid","Invalid") -> Valid | AJ2: =IF(AND(G2>=0,G2<=2),"Valid","Invalid") -> Valid | AK2: =IF(AND(ISNUMBER(H2),H2>=DATE(2012,1,1),H2<=DATE(2014,12,31)),"Valid ","Invalid") -> Valid | AL2: =IF(AND(Audit_Data[[#This Row],[Recency]]>=0,Audit_Data[[#This Row],[Recency]]<=100),"Valid","Invalid") -> Valid | AM2: =IF(AND(ISNUMBER(J2),J2>=0,ISNUMBER(K2),K2>=0,ISNUMBER(L2),L2>=0,ISNUMBER(M2),M2>=0,ISNUMBER(N2),N2>=0,ISNUMBER(O2),O2>=0),"Valid","Invalid") -> Valid | AN2: =IF(AND(ISNUMBER(P2),P2>=0,ISNUMBER(Q2),Q2>=0,ISNUMBER(R2),R2>=0,ISNUMBER(S2),S2>=0,ISNUMBER(T2),T2>=0),"Valid","Invalid") -> Valid | AO2: =IF(AND(U2<=1,V2<=1,W2<=1,X2<=1,Y2<=1),"Valid","Invalid") -> Valid | AP2: =IF(OR(Z2=0,Z2=1),"Valid","Invalid") -> Valid | AQ2: =IF(Audit_Data[[#This Row],[Z_CostContact]]=3,"Valid","Invalid") -> Valid | AR2: =IF(AB2=11,"Valid","Invalid") -> Valid | AS2: =IF(OR(AC2=0,AC2=1),"Valid","Invalid") -> Valid
A3: 2174 | B3: 1954 | C3: Graduation | D3: Single | E3: 46344 | F3: 1 | G3: 1 | H3: 41706 | I3: 38 | J3: 11 | K3: 1 | L3: 6 | M3: 2 | N3: 1 | O3: 6 | P3: 2 | Q3: 1 | R3: 1 | S3: 2 | T3: 5 | U3: 0 | V3: 0 | W3: 0 | X3: 0 | Y3: 0 | Z3: 0 | AA3: 3 | AB3: 11 | AC3: 0 | AD3: =IF(COUNTIF(A:A,A3)>1,"Duplicate","Ok") -> Ok | AE3: =IF(AND(Audit_Data[[#This Row],[Year_Birth]]>=1900,Audit_Data[[#This Row],[Year_Birth]]<=2010),"OK","Invalid") -> OK | AF3: =IF(OR(C3="Graduation",C3="phD",C3="Master",C3="Basic",C3="2n Cycle"),"Valid","Invalid") -> Valid | AG3: =IF(OR(D3="Single",D3="Married",D3="Divorced",D3="Together",D3="Widow",D3="Alone"),"Valid","Invalid") -> Valid | AH3: =IF(AND(ISNUMBER(E3),E3<>""),"Valid","Invalid") -> Valid | AI3: =IF(AND(F3>=0,F3<=2),"Valid","Invalid") -> Valid | AJ3: =IF(AND(G3>=0,G3<=2),"Valid","Invalid") -> Valid | AK3: =IF(AND(ISNUMBER(H3),H3>=DATE(2012,1,1),H3<=DATE(2014,12,31)),"Valid ","Invalid") -> Valid | AL3: =IF(AND(Audit_Data[[#This Row],[Recency]]>=0,Audit_Data[[#This Row],[Recency]]<=100),"Valid","Invalid") -> Valid | AM3: =IF(AND(ISNUMBER(J3),J3>=0,ISNUMBER(K3),K3>=0,ISNUMBER(L3),L3>=0,ISNUMBER(M3),M3>=0,ISNUMBER(N3),N3>=0,ISNUMBER(O3),O3>=0),"Valid","Invalid") -> Valid | AN3: =IF(AND(ISNUMBER(P3),P3>=0,ISNUMBER(Q3),Q3>=0,ISNUMBER(R3),R3>=0,ISNUMBER(S3),S3>=0,ISNUMBER(T3),T3>=0),"Valid","Invalid") -> Valid | AO3: =IF(AND(U3<=1,V3<=1,W3<=1,X3<=1,Y3<=1),"Valid","Invalid") -> Valid | AP3: =IF(OR(Z3=0,Z3=1),"Valid","Invalid") -> Valid | AQ3: =IF(Audit_Data[[#This Row],[Z_CostContact]]=3,"Valid","Invalid") -> Valid | AR3: =IF(AB3=11,"Valid","Invalid") -> Valid | AS3: =IF(OR(AC3=0,AC3=1),"Valid","Invalid") -> Valid
A4: 4141 | B4: 1965 | C4: Graduation | D4: Together | E4: 71613 | F4: 0 | G4: 0 | H4: 41507 | I4: 26 | J4: 426 | K4: 49 | L4: 127 | M4: 111 | N4: 21 | O4: 42 | P4: 1 | Q4: 8 | R4: 2 | S4: 10 | T4: 4 | U4: 0 | V4: 0 | W4: 0 | X4: 0 | Y4: 0 | Z4: 0 | AA4: 3 | AB4: 11 | AC4: 0 | AD4: =IF(COUNTIF(A:A,A4)>1,"Duplicate","Ok") -> Ok | AE4: =IF(AND(Audit_Data[[#This Row],[Year_Birth]]>=1900,Audit_Data[[#This Row],[Year_Birth]]<=2010),"OK","Invalid") -> OK | AF4: =IF(OR(C4="Graduation",C4="phD",C4="Master",C4="Basic",C4="2n Cycle"),"Valid","Invalid") -> Valid | AG4: =IF(OR(D4="Single",D4="Married",D4="Divorced",D4="Together",D4="Widow",D4="Alone"),"Valid","Invalid") -> Valid | AH4: =IF(AND(ISNUMBER(E4),E4<>""),"Valid","Invalid") -> Valid | AI4: =IF(AND(F4>=0,F4<=2),"Valid","Invalid") -> Valid | AJ4: =IF(AND(G4>=0,G4<=2),"Valid","Invalid") -> Valid | AK4: =IF(AND(ISNUMBER(H4),H4>=DATE(2012,1,1),H4<=DATE(2014,12,31)),"Valid ","Invalid") -> Valid | AL4: =IF(AND(Audit_Data[[#This Row],[Recency]]>=0,Audit_Data[[#This Row],[Recency]]<=100),"Valid","Invalid") -> Valid | AM4: =IF(AND(ISNUMBER(J4),J4>=0,ISNUMBER(K4),K4>=0,ISNUMBER(L4),L4>=0,ISNUMBER(M4),M4>=0,ISNUMBER(N4),N4>=0,ISNUMBER(O4),O4>=0),"Valid","Invalid") -> Valid | AN4: =IF(AND(ISNUMBER(P4),P4>=0,ISNUMBER(Q4),Q4>=0,ISNUMBER(R4),R4>=0,ISNUMBER(S4),S4>=0,ISNUMBER(T4),T4>=0),"Valid","Invalid") -> Valid | AO4: =IF(AND(U4<=1,V4<=1,W4<=1,X4<=1,Y4<=1),"Valid","Invalid") -> Valid | AP4: =IF(OR(Z4=0,Z4=1),"Valid","Invalid") -> Valid | AQ4: =IF(Audit_Data[[#This Row],[Z_CostContact]]=3,"Valid","Invalid") -> Valid | AR4: =IF(AB4=11,"Valid","Invalid") -> Valid | AS4: =IF(OR(AC4=0,AC4=1),"Valid","Invalid") -> Valid
A5: 6182 | B5: 1984 | C5: Graduation | D5: Together | E5: 26646 | F5: 1 | G5: 0 | H5: 41680 | I5: 26 | J5: 11 | K5: 4 | L5: 20 | M5: 10 | N5: 3 | O5: 5 | P5: 2 | Q5: 2 | R5: 0 | S5: 4 | T5: 6 | U5: 0 | V5: 0 | W5: 0 | X5: 0 | Y5: 0 | Z5: 0 | AA5: 3 | AB5: 11 | AC5: 0 | AD5: =IF(COUNTIF(A:A,A5)>1,"Duplicate","Ok") -> Ok | AE5: =IF(AND(Audit_Data[[#This Row],[Year_Birth]]>=1900,Audit_Data[[#This Row],[Year_Birth]]<=2010),"OK","Invalid") -> OK | AF5: =IF(OR(C5="Graduation",C5="phD",C5="Master",C5="Basic",C5="2n Cycle"),"Valid","Invalid") -> Valid | AG5: =IF(OR(D5="Single",D5="Married",D5="Divorced",D5="Together",D5="Widow",D5="Alone"),"Valid","Invalid") -> Valid | AH5: =IF(AND(ISNUMBER(E5),E5<>""),"Valid","Invalid") -> Valid | AI5: =IF(AND(F5>=0,F5<=2),"Valid","Invalid") -> Valid | AJ5: =IF(AND(G5>=0,G5<=2),"Valid","Invalid") -> Valid | AK5: =IF(AND(ISNUMBER(H5),H5>=DATE(2012,1,1),H5<=DATE(2014,12,31)),"Valid ","Invalid") -> Valid | AL5: =IF(AND(Audit_Data[[#This Row],[Recency]]>=0,Audit_Data[[#This Row],[Recency]]<=100),"Valid","Invalid") -> Valid | AM5: =IF(AND(ISNUMBER(J5),J5>=0,ISNUMBER(K5),K5>=0,ISNUMBER(L5),L5>=0,ISNUMBER(M5),M5>=0,ISNUMBER(N5),N5>=0,ISNUMBER(O5),O5>=0),"Valid","Invalid") -> Valid | AN5: =IF(AND(ISNUMBER(P5),P5>=0,ISNUMBER(Q5),Q5>=0,ISNUMBER(R5),R5>=0,ISNUMBER(S5),S5>=0,ISNUMBER(T5),T5>=0),"Valid","Invalid") -> Valid | AO5: =IF(AND(U5<=1,V5<=1,W5<=1,X5<=1,Y5<=1),"Valid","Invalid") -> Valid | AP5: =IF(OR(Z5=0,Z5=1),"Valid","Invalid") -> Valid | AQ5: =IF(Audit_Data[[#This Row],[Z_CostContact]]=3,"Valid","Invalid") -> Valid | AR5: =IF(AB5=11,"Valid","Invalid") -> Valid | AS5: =IF(OR(AC5=0,AC5=1),"Valid","Invalid") -> Valid
A6: 5324 | B6: 1981 | C6: PhD | D6: Married | E6: 58293 | F6: 1 | G6: 0 | H6: 41658 | I6: 94 | J6: 173 | K6: 43 | L6: 118 | M6: 46 | N6: 27 | O6: 15 | P6: 5 | Q6: 5 | R6: 3 | S6: 6 | T6: 5 | U6: 0 | V6: 0 | W6: 0 | X6: 0 | Y6: 0 | Z6: 0 | AA6: 3 | AB6: 11 | AC6: 0 | AD6: =IF(COUNTIF(A:A,A6)>1,"Duplicate","Ok") -> Ok | AE6: =IF(AND(Audit_Data[[#This Row],[Year_Birth]]>=1900,Audit_Data[[#This Row],[Year_Birth]]<=2010),"OK","Invalid") -> OK | AF6: =IF(OR(C6="Graduation",C6="phD",C6="Master",C6="Basic",C6="2n Cycle"),"Valid","Invalid") -> Valid | AG6: =IF(OR(D6="Single",D6="Married",D6="Divorced",D6="Together",D6="Widow",D6="Alone"),"Valid","Invalid") -> Valid | AH6: =IF(AND(ISNUMBER(E6),E6<>""),"Valid","Invalid") -> Valid | AI6: =IF(AND(F6>=0,F6<=2),"Valid","Invalid") -> Valid | AJ6: =IF(AND(G6>=0,G6<=2),"Valid","Invalid") -> Valid | AK6: =IF(AND(ISNUMBER(H6),H6>=DATE(2012,1,1),H6<=DATE(2014,12,31)),"Valid ","Invalid") -> Valid | AL6: =IF(AND(Audit_Data[[#This Row],[Recency]]>=0,Audit_Data[[#This Row],[Recency]]<=100),"Valid","Invalid") -> Valid | AM6: =IF(AND(ISNUMBER(J6),J6>=0,ISNUMBER(K6),K6>=0,ISNUMBER(L6),L6>=0,ISNUMBER(M6),M6>=0,ISNUMBER(N6),N6>=0,ISNUMBER(O6),O6>=0),"Valid","Invalid") -> Valid | AN6: =IF(AND(ISNUMBER(P6),P6>=0,ISNUMBER(Q6),Q6>=0,ISNUMBER(R6),R6>=0,ISNUMBER(S6),S6>=0,ISNUMBER(T6),T6>=0),"Valid","Invalid") -> Valid | AO6: =IF(AND(U6<=1,V6<=1,W6<=1,X6<=1,Y6<=1),"Valid","Invalid") -> Valid | AP6: =IF(OR(Z6=0,Z6=1),"Valid","Invalid") -> Valid | AQ6: =IF(Audit_Data[[#This Row],[Z_CostContact]]=3,"Valid","Invalid") -> Valid | AR6: =IF(AB6=11,"Valid","Invalid") -> Valid | AS6: =IF(OR(AC6=0,AC6=1),"Valid","Invalid") -> Valid
A7: 7446 | B7: 1967 | C7: Master | D7: Together | E7: 62513 | F7: 0 | G7: 1 | H7: 41526 | I7: 16 | J7: 520 | K7: 42 | L7: 98 | M7: 0 | N7: 42 | O7: 14 | P7: 2 | Q7: 6 | R7: 4 | S7: 10 | T7: 6 | U7: 0 | V7: 0 | W7: 0 | X7: 0 | Y7: 0 | Z7: 0 | AA7: 3 | AB7: 11 | AC7: 0 | AD7: =IF(COUNTIF(A:A,A7)>1,"Duplicate","Ok") -> Ok | AE7: =IF(AND(Audit_Data[[#This Row],[Year_Birth]]>=1900,Audit_Data[[#This Row],[Year_Birth]]<=2010),"OK","Invalid") -> OK | AF7: =IF(OR(C7="Graduation",C7="phD",C7="Master",C7="Basic",C7="2n Cycle"),"Valid","Invalid") -> Valid | AG7: =IF(OR(D7="Single",D7="Married",D7="Divorced",D7="Together",D7="Widow",D7="Alone"),"Valid","Invalid") -> Valid | AH7: =IF(AND(ISNUMBER(E7),E7<>""),"Valid","Invalid") -> Valid | AI7: =IF(AND(F7>=0,F7<=2),"Valid","Invalid") -> Valid | AJ7: =IF(AND(G7>=0,G7<=2),"Valid","Invalid") -> Valid | AK7: =IF(AND(ISNUMBER(H7),H7>=DATE(2012,1,1),H7<=DATE(2014,12,31)),"Valid ","Invalid") -> Valid | AL7: =IF(AND(Audit_Data[[#This Row],[Recency]]>=0,Audit_Data[[#This Row],[Recency]]<=100),"Valid","Invalid") -> Valid | AM7: =IF(AND(ISNUMBER(J7),J7>=0,ISNUMBER(K7),K7>=0,ISNUMBER(L7),L7>=0,ISNUMBER(M7),M7>=0,ISNUMBER(N7),N7>=0,ISNUMBER(O7),O7>=0),"Valid","Invalid") -> Valid | AN7: =IF(AND(ISNUMBER(P7),P7>=0,ISNUMBER(Q7),Q7>=0,ISNUMBER(R7),R7>=0,ISNUMBER(S7),S7>=0,ISNUMBER(T7),T7>=0),"Valid","Invalid") -> Valid | AO7: =IF(AND(U7<=1,V7<=1,W7<=1,X7<=1,Y7<=1),"Valid","Invalid") -> Valid | AP7: =IF(OR(Z7=0,Z7=1),"Valid","Invalid") -> Valid | AQ7: =IF(Audit_Data[[#This Row],[Z_CostContact]]=3,"Valid","Invalid") -> Valid | AR7: =IF(AB7=11,"Valid","Invalid") -> Valid | AS7: =IF(OR(AC7=0,AC7=1),"Valid","Invalid") -> Valid
A8: 965 | B8: 1971 | C8: Graduation | D8: Divorced | E8: 55635 | F8: 0 | G8: 1 | H8: 41226 | I8: 34 | J8: 235 | K8: 65 | L8: 164 | M8: 50 | N8: 49 | O8: 27 | P8: 4 | Q8: 7 | R8: 3 | S8: 7 | T8: 6 | U8: 0 | V8: 0 | W8: 0 | X8: 0 | Y8: 0 | Z8: 0 | AA8: 3 | AB8: 11 | AC8: 0 | AD8: =IF(COUNTIF(A:A,A8)>1,"Duplicate","Ok") -> Ok | AE8: =IF(AND(Audit_Data[[#This Row],[Year_Birth]]>=1900,Audit_Data[[#This Row],[Year_Birth]]<=2010),"OK","Invalid") -> OK | AF8: =IF(OR(C8="Graduation",C8="phD",C8="Master",C8="Basic",C8="2n Cycle"),"Valid","Invalid") -> Valid | AG8: =IF(OR(D8="Single",D8="Married",D8="Divorced",D8="Together",D8="Widow",D8="Alone"),"Valid","Invalid") -> Valid | AH8: =IF(AND(ISNUMBER(E8),E8<>""),"Valid","Invalid") -> Valid | AI8: =IF(AND(F8>=0,F8<=2),"Valid","Invalid") -> Valid | AJ8: =IF(AND(G8>=0,G8<=2),"Valid","Invalid") -> Valid | AK8: =IF(AND(ISNUMBER(H8),H8>=DATE(2012,1,1),H8<=DATE(2014,12,31)),"Valid ","Invalid") -> Valid | AL8: =IF(AND(Audit_Data[[#This Row],[Recency]]>=0,Audit_Data[[#This Row],[Recency]]<=100),"Valid","Invalid") -> Valid | AM8: =IF(AND(ISNUMBER(J8),J8>=0,ISNUMBER(K8),K8>=0,ISNUMBER(L8),L8>=0,ISNUMBER(M8),M8>=0,ISNUMBER(N8),N8>=0,ISNUMBER(O8),O8>=0),"Valid","Invalid") -> Valid | AN8: =IF(AND(ISNUMBER(P8),P8>=0,ISNUMBER(Q8),Q8>=0,ISNUMBER(R8),R8>=0,ISNUMBER(S8),S8>=0,ISNUMBER(T8),T8>=0),"Valid","Invalid") -> Valid | AO8: =IF(AND(U8<=1,V8<=1,W8<=1,X8<=1,Y8<=1),"Valid","Invalid") -> Valid | AP8: =IF(OR(Z8=0,Z8=1),"Valid","Invalid") -> Valid | AQ8: =IF(Audit_Data[[#This Row],[Z_CostContact]]=3,"Valid","Invalid") -> Valid | AR8: =IF(AB8=11,"Valid","Invalid") -> Valid | AS8: =IF(OR(AC8=0,AC8=1),"Valid","Invalid") -> Valid
A9: 6177 | B9: 1985 | C9: PhD | D9: Married | E9: 33454 | F9: 1 | G9: 0 | H9: 41402 | I9: 32 | J9: 76 | K9: 10 | L9: 56 | M9: 3 | N9: 1 | O9: 23 | P9: 2 | Q9: 4 | R9: 0 | S9: 4 | T9: 8 | U9: 0 | V9: 0 | W9: 0 | X9: 0 | Y9: 0 | Z9: 0 | AA9: 3 | AB9: 11 | AC9: 0 | AD9: =IF(COUNTIF(A:A,A9)>1,"Duplicate","Ok") -> Ok | AE9: =IF(AND(Audit_Data[[#This Row],[Year_Birth]]>=1900,Audit_Data[[#This Row],[Year_Birth]]<=2010),"OK","Invalid") -> OK | AF9: =IF(OR(C9="Graduation",C9="phD",C9="Master",C9="Basic",C9="2n Cycle"),"Valid","Invalid") -> Valid | AG9: =IF(OR(D9="Single",D9="Married",D9="Divorced",D9="Together",D9="Widow",D9="Alone"),"Valid","Invalid") -> Valid | AH9: =IF(AND(ISNUMBER(E9),E9<>""),"Valid","Invalid") -> Valid | AI9: =IF(AND(F9>=0,F9<=2),"Valid","Invalid") -> Valid | AJ9: =IF(AND(G9>=0,G9<=2),"Valid","Invalid") -> Valid | AK9: =IF(AND(ISNUMBER(H9),H9>=DATE(2012,1,1),H9<=DATE(2014,12,31)),"Valid ","Invalid") -> Valid | AL9: =IF(AND(Audit_Data[[#This Row],[Recency]]>=0,Audit_Data[[#This Row],[Recency]]<=100),"Valid","Invalid") -> Valid | AM9: =IF(AND(ISNUMBER(J9),J9>=0,ISNUMBER(K9),K9>=0,ISNUMBER(L9),L9>=0,ISNUMBER(M9),M9>=0,ISNUMBER(N9),N9>=0,ISNUMBER(O9),O9>=0),"Valid","Invalid") -> Valid | AN9: =IF(AND(ISNUMBER(P9),P9>=0,ISNUMBER(Q9),Q9>=0,ISNUMBER(R9),R9>=0,ISNUMBER(S9),S9>=0,ISNUMBER(T9),T9>=0),"Valid","Invalid") -> Valid | AO9: =IF(AND(U9<=1,V9<=1,W9<=1,X9<=1,Y9<=1),"Valid","Invalid") -> Valid | AP9: =IF(OR(Z9=0,Z9=1),"Valid","Invalid") -> Valid | AQ9: =IF(Audit_Data[[#This Row],[Z_CostContact]]=3,"Valid","Invalid") -> Valid | AR9: =IF(AB9=11,"Valid","Invalid") -> Valid | AS9: =IF(OR(AC9=0,AC9=1),"Valid","Invalid") -> Valid
A10: 4855 | B10: 1974 | C10: PhD | D10: Together | E10: 30351 | F10: 1 | G10: 0 | H10: 41431 | I10: 19 | J10: 14 | K10: 0 | L10: 24 | M10: 3 | N10: 3 | O10: 2 | P10: 1 | Q10: 3 | R10: 0 | S10: 2 | T10: 9 | U10: 0 | V10: 0 | W10: 0 | X10: 0 | Y10: 0 | Z10: 0 | AA10: 3 | AB10: 11 | AC10: 1 | AD10: =IF(COUNTIF(A:A,A10)>1,"Duplicate","Ok") -> Ok | AE10: =IF(AND(Audit_Data[[#This Row],[Year_Birth]]>=1900,Audit_Data[[#This Row],[Year_Birth]]<=2010),"OK","Invalid") -> OK | AF10: =IF(OR(C10="Graduation",C10="phD",C10="Master",C10="Basic",C10="2n Cycle"),"Valid","Invalid") -> Valid | AG10: =IF(OR(D10="Single",D10="Married",D10="Divorced",D10="Together",D10="Widow",D10="Alone"),"Valid","Invalid") -> Valid | AH10: =IF(AND(ISNUMBER(E10),E10<>""),"Valid","Invalid") -> Valid | AI10: =IF(AND(F10>=0,F10<=2),"Valid","Invalid") -> Valid | AJ10: =IF(AND(G10>=0,G10<=2),"Valid","Invalid") -> Valid | AK10: =IF(AND(ISNUMBER(H10),H10>=DATE(2012,1,1),H10<=DATE(2014,12,31)),"Valid ","Invalid") -> Valid | AL10: =IF(AND(Audit_Data[[#This Row],[Recency]]>=0,Audit_Data[[#This Row],[Recency]]<=100),"Valid","Invalid") -> Valid | AM10: =IF(AND(ISNUMBER(J10),J10>=0,ISNUMBER(K10),K10>=0,ISNUMBER(L10),L10>=0,ISNUMBER(M10),M10>=0,ISNUMBER(N10),N10>=0,ISNUMBER(O10),O10>=0),"Valid","Invalid") -> Valid | AN10: =IF(AND(ISNUMBER(P10),P10>=0,ISNUMBER(Q10),Q10>=0,ISNUMBER(R10),R10>=0,ISNUMBER(S10),S10>=0,ISNUMBER(T10),T10>=0),"Valid","Invalid") -> Valid | AO10: =IF(AND(U10<=1,V10<=1,W10<=1,X10<=1,Y10<=1),"Valid","Invalid") -> Valid | AP10: =IF(OR(Z10=0,Z10=1),"Valid","Invalid") -> Valid | AQ10: =IF(Audit_Data[[#This Row],[Z_CostContact]]=3,"Valid","Invalid") -> Valid | AR10: =IF(AB10=11,"Valid","Invalid") -> Valid | AS10: =IF(OR(AC10=0,AC10=1),"Valid","Invalid") -> Valid
A11: 5899 | B11: 1950 | C11: PhD | D11: Together | E11: 5648 | F11: 1 | G11: 1 | H11: 41711 | I11: 68 | J11: 28 | K11: 0 | L11: 6 | M11: 1 | N11: 1 | O11: 13 | P11: 1 | Q11: 1 | R11: 0 | S11: 0 | T11: 20 | U11: 1 | V11: 0 | W11: 0 | X11: 0 | Y11: 0 | Z11: 0 | AA11: 3 | AB11: 11 | AC11: 0 | AD11: =IF(COUNTIF(A:A,A11)>1,"Duplicate","Ok") -> Ok | AE11: =IF(AND(Audit_Data[[#This Row],[Year_Birth]]>=1900,Audit_Data[[#This Row],[Year_Birth]]<=2010),"OK","Invalid") -> OK | AF11: =IF(OR(C11="Graduation",C11="phD",C11="Master",C11="Basic",C11="2n Cycle"),"Valid","Invalid") -> Valid | AG11: =IF(OR(D11="Single",D11="Married",D11="Divorced",D11="Together",D11="Widow",D11="Alone"),"Valid","Invalid") -> Valid | AH11: =IF(AND(ISNUMBER(E11),E11<>""),"Valid","Invalid") -> Valid | AI11: =IF(AND(F11>=0,F11<=2),"Valid","Invalid") -> Valid | AJ11: =IF(AND(G11>=0,G11<=2),"Valid","Invalid") -> Valid | AK11: =IF(AND(ISNUMBER(H11),H11>=DATE(2012,1,1),H11<=DATE(2014,12,31)),"Valid ","Invalid") -> Valid | AL11: =IF(AND(Audit_Data[[#This Row],[Recency]]>=0,Audit_Data[[#This Row],[Recency]]<=100),"Valid","Invalid") -> Valid | AM11: =IF(AND(ISNUMBER(J11),J11>=0,ISNUMBER(K11),K11>=0,ISNUMBER(L11),L11>=0,ISNUMBER(M11),M11>=0,ISNUMBER(N11),N11>=0,ISNUMBER(O11),O11>=0),"Valid","Invalid") -> Valid | AN11: =IF(AND(ISNUMBER(P11),P11>=0,ISNUMBER(Q11),Q11>=0,ISNUMBER(R11),R11>=0,ISNUMBER(S11),S11>=0,ISNUMBER(T11),T11>=0),"Valid","Invalid") -> Valid | AO11: =IF(AND(U11<=1,V11<=1,W11<=1,X11<=1,Y11<=1),"Valid","Invalid") -> Valid | AP11: =IF(OR(Z11=0,Z11=1),"Valid","Invalid") -> Valid | AQ11: =IF(Audit_Data[[#This Row],[Z_CostContact]]=3,"Valid","Invalid") -> Valid | AR11: =IF(AB11=11,"Valid","Invalid") -> Valid | AS11: =IF(OR(AC11=0,AC11=1),"Valid","Invalid") -> Valid
A12: 1994 | B12: 1983 | C12: Graduation | D12: Married | F12: 1 | G12: 0 | H12: 41593 | I12: 11 | J12: 5 | K12: 5 | L12: 6 | M12: 0 | N12: 2 | O12: 1 | P12: 1 | Q12: 1 | R12: 0 | S12: 2 | T12: 7 | U12: 0 | V12: 0 | W12: 0 | X12: 0 | Y12: 0 | Z12: 0 | AA12: 3 | AB12: 11 | AC12: 0 | AD12: =IF(COUNTIF(A:A,A12)>1,"Duplicate","Ok") -> Ok | AE12: =IF(AND(Audit_Data[[#This Row],[Year_Birth]]>=1900,Audit_Data[[#This Row],[Year_Birth]]<=2010),"OK","Invalid") -> OK | AF12: =IF(OR(C12="Graduation",C12="phD",C12="Master",C12="Basic",C12="2n Cycle"),"Valid","Invalid") -> Valid | AG12: =IF(OR(D12="Single",D12="Married",D12="Divorced",D12="Together",D12="Widow",D12="Alone"),"Valid","Invalid") -> Valid | AH12: =IF(AND(ISNUMBER(E12),E12<>""),"Valid","Invalid") -> Invalid | AI12: =IF(AND(F12>=0,F12<=2),"Valid","Invalid") -> Valid | AJ12: =IF(AND(G12>=0,G12<=2),"Valid","Invalid") -> Valid | AK12: =IF(AND(ISNUMBER(H12),H12>=DATE(2012,1,1),H12<=DATE(2014,12,31)),"Valid ","Invalid") -> Valid | AL12: =IF(AND(Audit_Data[[#This Row],[Recency]]>=0,Audit_Data[[#This Row],[Recency]]<=100),"Valid","Invalid") -> Valid | AM12: =IF(AND(ISNUMBER(J12),J12>=0,ISNUMBER(K12),K12>=0,ISNUMBER(L12),L12>=0,ISNUMBER(M12),M12>=0,ISNUMBER(N12),N12>=0,ISNUMBER(O12),O12>=0),"Valid","Invalid") -> Valid | AN12: =IF(AND(ISNUMBER(P12),P12>=0,ISNUMBER(Q12),Q12>=0,ISNUMBER(R12),R12>=0,ISNUMBER(S12),S12>=0,ISNUMBER(T12),T12>=0),"Valid","Invalid") -> Valid | AO12: =IF(AND(U12<=1,V12<=1,W12<=1,X12<=1,Y12<=1),"Valid","Invalid") -> Valid | AP12: =IF(OR(Z12=0,Z12=1),"Valid","Invalid") -> Valid | AQ12: =IF(Audit_Data[[#This Row],[Z_CostContact]]=3,"Valid","Invalid") -> Valid | AR12: =IF(AB12=11,"Valid","Invalid") -> Valid | AS12: =IF(OR(AC12=0,AC12=1),"Valid","Invalid") -> Valid
A13: 387 | B13: 1976 | C13: Basic | D13: Married | E13: 7500 | F13: 0 | G13: 0 | H13: 41226 | I13: 59 | J13: 6 | K13: 16 | L13: 11 | M13: 11 | N13: 1 | O13: 16 | P13: 1 | Q13: 2 | R13: 0 | S13: 3 | T13: 8 | U13: 0 | V13: 0 | W13: 0 | X13: 0 | Y13: 0 | Z13: 0 | AA13: 3 | AB13: 11 | AC13: 0 | AD13: =IF(COUNTIF(A:A,A13)>1,"Duplicate","Ok") -> Ok | AE13: =IF(AND(Audit_Data[[#This Row],[Year_Birth]]>=1900,Audit_Data[[#This Row],[Year_Birth]]<=2010),"OK","Invalid") -> OK | AF13: =IF(OR(C13="Graduation",C13="phD",C13="Master",C13="Basic",C13="2n Cycle"),"Valid","Invalid") -> Valid | AG13: =IF(OR(D13="Single",D13="Married",D13="Divorced",D13="Together",D13="Widow",D13="Alone"),"Valid","Invalid") -> Valid | AH13: =IF(AND(ISNUMBER(E13),E13<>""),"Valid","Invalid") -> Valid | AI13: =IF(AND(F13>=0,F13<=2),"Valid","Invalid") -> Valid | AJ13: =IF(AND(G13>=0,G13<=2),"Valid","Invalid") -> Valid | AK13: =IF(AND(ISNUMBER(H13),H13>=DATE(2012,1,1),H13<=DATE(2014,12,31)),"Valid ","Invalid") -> Valid | AL13: =IF(AND(Audit_Data[[#This Row],[Recency]]>=0,Audit_Data[[#This Row],[Recency]]<=100),"Valid","Invalid") -> Valid | AM13: =IF(AND(ISNUMBER(J13),J13>=0,ISNUMBER(K13),K13>=0,ISNUMBER(L13),L13>=0,ISNUMBER(M13),M13>=0,ISNUMBER(N13),N13>=0,ISNUMBER(O13),O13>=0),"Valid","Invalid") -> Valid | AN13: =IF(AND(ISNUMBER(P13),P13>=0,ISNUMBER(Q13),Q13>=0,ISNUMBER(R13),R13>=0,ISNUMBER(S13),S13>=0,ISNUMBER(T13),T13>=0),"Valid","Invalid") -> Valid | AO13: =IF(AND(U13<=1,V13<=1,W13<=1,X13<=1,Y13<=1),"Valid","Invalid") -> Valid | AP13: =IF(OR(Z13=0,Z13=1),"Valid","Invalid") -> Valid | AQ13: =IF(Audit_Data[[#This Row],[Z_CostContact]]=3,"Valid","Invalid") -> Valid | AR13: =IF(AB13=11,"Valid","Invalid") -> Valid | AS13: =IF(OR(AC13=0,AC13=1),"Valid","Invalid") -> Valid
A14: 2125 | B14: 1959 | C14: Graduation | D14: Divorced | E14: 63033 | F14: 0 | G14: 0 | H14: 41593 | I14: 82 | J14: 194 | K14: 61 | L14: 480 | M14: 225 | N14: 112 | O14: 30 | P14: 1 | Q14: 3 | R14: 4 | S14: 8 | T14: 2 | U14: 0 | V14: 0 | W14: 0 | X14: 0 | Y14: 0 | Z14: 0 | AA14: 3 | AB14: 11 | AC14: 0 | AD14: =IF(COUNTIF(A:A,A14)>1,"Duplicate","Ok") -> Ok | AE14: =IF(AND(Audit_Data[[#This Row],[Year_Birth]]>=1900,Audit_Data[[#This Row],[Year_Birth]]<=2010),"OK","Invalid") -> OK | AF14: =IF(OR(C14="Graduation",C14="phD",C14="Master",C14="Basic",C14="2n Cycle"),"Valid","Invalid") -> Valid | AG14: =IF(OR(D14="Single",D14="Married",D14="Divorced",D14="Together",D14="Widow",D14="Alone"),"Valid","Invalid") -> Valid | AH14: =IF(AND(ISNUMBER(E14),E14<>""),"Valid","Invalid") -> Valid | AI14: =IF(AND(F14>=0,F14<=2),"Valid","Invalid") -> Valid | AJ14: =IF(AND(G14>=0,G14<=2),"Valid","Invalid") -> Valid | AK14: =IF(AND(ISNUMBER(H14),H14>=DATE(2012,1,1),H14<=DATE(2014,12,31)),"Valid ","Invalid") -> Valid | AL14: =IF(AND(Audit_Data[[#This Row],[Recency]]>=0,Audit_Data[[#This Row],[Recency]]<=100),"Valid","Invalid") -> Valid | AM14: =IF(AND(ISNUMBER(J14),J14>=0,ISNUMBER(K14),K14>=0,ISNUMBER(L14),L14>=0,ISNUMBER(M14),M14>=0,ISNUMBER(N14),N14>=0,ISNUMBER(O14),O14>=0),"Valid","Invalid") -> Valid | AN14: =IF(AND(ISNUMBER(P14),P14>=0,ISNUMBER(Q14),Q14>=0,ISNUMBER(R14),R14>=0,ISNUMBER(S14),S14>=0,ISNUMBER(T14),T14>=0),"Valid","Invalid") -> Valid | AO14: =IF(AND(U14<=1,V14<=1,W14<=1,X14<=1,Y14<=1),"Valid","Invalid") -> Valid | AP14: =IF(OR(Z14=0,Z14=1),"Valid","Invalid") -> Valid | AQ14: =IF(Audit_Data[[#This Row],[Z_CostContact]]=3,"Valid","Invalid") -> Valid | AR14: =IF(AB14=11,"Valid","Invalid") -> Valid | AS14: =IF(OR(AC14=0,AC14=1),"Valid","Invalid") -> Valid
A15: 8180 | B15: 1952 | C15: Master | D15: Divorced | E15: 59354 | F15: 1 | G15: 1 | H15: 41593 | I15: 53 | J15: 233 | K15: 2 | L15: 53 | M15: 3 | N15: 5 | O15: 14 | P15: 3 | Q15: 6 | R15: 1 | S15: 5 | T15: 6 | U15: 0 | V15: 0 | W15: 0 | X15: 0 | Y15: 0 | Z15: 0 | AA15: 3 | AB15: 11 | AC15: 0 | AD15: =IF(COUNTIF(A:A,A15)>1,"Duplicate","Ok") -> Ok | AE15: =IF(AND(Audit_Data[[#This Row],[Year_Birth]]>=1900,Audit_Data[[#This Row],[Year_Birth]]<=2010),"OK","Invalid") -> OK | AF15: =IF(OR(C15="Graduation",C15="phD",C15="Master",C15="Basic",C15="2n Cycle"),"Valid","Invalid") -> Valid | AG15: =IF(OR(D15="Single",D15="Married",D15="Divorced",D15="Together",D15="Widow",D15="Alone"),"Valid","Invalid") -> Valid | AH15: =IF(AND(ISNUMBER(E15),E15<>""),"Valid","Invalid") -> Valid | AI15: =IF(AND(F15>=0,F15<=2),"Valid","Invalid") -> Valid | AJ15: =IF(AND(G15>=0,G15<=2),"Valid","Invalid") -> Valid | AK15: =IF(AND(ISNUMBER(H15),H15>=DATE(2012,1,1),H15<=DATE(2014,12,31)),"Valid ","Invalid") -> Valid | AL15: =IF(AND(Audit_Data[[#This Row],[Recency]]>=0,Audit_Data[[#This Row],[Recency]]<=100),"Valid","Invalid") -> Valid | AM15: =IF(AND(ISNUMBER(J15),J15>=0,ISNUMBER(K15),K15>=0,ISNUMBER(L15),L15>=0,ISNUMBER(M15),M15>=0,ISNUMBER(N15),N15>=0,ISNUMBER(O15),O15>=0),"Valid","Invalid") -> Valid | AN15: =IF(AND(ISNUMBER(P15),P15>=0,ISNUMBER(Q15),Q15>=0,ISNUMBER(R15),R15>=0,ISNUMBER(S15),S15>=0,ISNUMBER(T15),T15>=0),"Valid","Invalid") -> Valid | AO15: =IF(AND(U15<=1,V15<=1,W15<=1,X15<=1,Y15<=1),"Valid","Invalid") -> Valid | AP15: =IF(OR(Z15=0,Z15=1),"Valid","Invalid") -> Valid | AQ15: =IF(Audit_Data[[#This Row],[Z_CostContact]]=3,"Valid","Invalid") -> Valid | AR15: =IF(AB15=11,"Valid","Invalid") -> Valid | AS15: =IF(OR(AC15=0,AC15=1),"Valid","Invalid") -> Valid
A16: 2569 | B16: 1987 | C16: Graduation | D16: Married | E16: 17323 | F16: 0 | G16: 0 | H16: 41192 | I16: 38 | J16: 3 | K16: 14 | L16: 17 | M16: 6 | N16: 1 | O16: 5 | P16: 1 | Q16: 1 | R16: 0 | S16: 3 | T16: 8 | U16: 0 | V16: 0 | W16: 0 | X16: 0 | Y16: 0 | Z16: 0 | AA16: 3 | AB16: 11 | AC16: 0 | AD16: =IF(COUNTIF(A:A,A16)>1,"Duplicate","Ok") -> Ok | AE16: =IF(AND(Audit_Data[[#This Row],[Year_Birth]]>=1900,Audit_Data[[#This Row],[Year_Birth]]<=2010),"OK","Invalid") -> OK | AF16: =IF(OR(C16="Graduation",C16="phD",C16="Master",C16="Basic",C16="2n Cycle"),"Valid","Invalid") -> Valid | AG16: =IF(OR(D16="Single",D16="Married",D16="Divorced",D16="Together",D16="Widow",D16="Alone"),"Valid","Invalid") -> Valid | AH16: =IF(AND(ISNUMBER(E16),E16<>""),"Valid","Invalid") -> Valid | AI16: =IF(AND(F16>=0,F16<=2),"Valid","Invalid") -> Valid | AJ16: =IF(AND(G16>=0,G16<=2),"Valid","Invalid") -> Valid | AK16: =IF(AND(ISNUMBER(H16),H16>=DATE(2012,1,1),H16<=DATE(2014,12,31)),"Valid ","Invalid") -> Valid | AL16: =IF(AND(Audit_Data[[#This Row],[Recency]]>=0,Audit_Data[[#This Row],[Recency]]<=100),"Valid","Invalid") -> Valid | AM16: =IF(AND(ISNUMBER(J16),J16>=0,ISNUMBER(K16),K16>=0,ISNUMBER(L16),L16>=0,ISNUMBER(M16),M16>=0,ISNUMBER(N16),N16>=0,ISNUMBER(O16),O16>=0),"Valid","Invalid") -> Valid | AN16: =IF(AND(ISNUMBER(P16),P16>=0,ISNUMBER(Q16),Q16>=0,ISNUMBER(R16),R16>=0,ISNUMBER(S16),S16>=0,ISNUMBER(T16),T16>=0),"Valid","Invalid") -> Valid | AO16: =IF(AND(U16<=1,V16<=1,W16<=1,X16<=1,Y16<=1),"Valid","Invalid") -> Valid | AP16: =IF(OR(Z16=0,Z16=1),"Valid","Invalid") -> Valid | AQ16: =IF(Audit_Data[[#This Row],[Z_CostContact]]=3,"Valid","Invalid") -> Valid | AR16: =IF(AB16=11,"Valid","Invalid") -> Valid | AS16: =IF(OR(AC16=0,AC16=1),"Valid","Invalid") -> Valid
A17: 2114 | B17: 1946 | C17: PhD | D17: Single | E17: 82800 | F17: 0 | G17: 0 | H17: 41237 | I17: 23 | J17: 1006 | K17: 22 | L17: 115 | M17: 59 | N17: 68 | O17: 45 | P17: 1 | Q17: 7 | R17: 6 | S17: 12 | T17: 3 | U17: 0 | V17: 0 | W17: 1 | X17: 1 | Y17: 0 | Z17: 0 | AA17: 3 | AB17: 11 | AC17: 1 | AD17: =IF(COUNTIF(A:A,A17)>1,"Duplicate","Ok") -> Ok | AE17: =IF(AND(Audit_Data[[#This Row],[Year_Birth]]>=1900,Audit_Data[[#This Row],[Year_Birth]]<=2010),"OK","Invalid") -> OK | AF17: =IF(OR(C17="Graduation",C17="phD",C17="Master",C17="Basic",C17="2n Cycle"),"Valid","Invalid") -> Valid | AG17: =IF(OR(D17="Single",D17="Married",D17="Divorced",D17="Together",D17="Widow",D17="Alone"),"Valid","Invalid") -> Valid | AH17: =IF(AND(ISNUMBER(E17),E17<>""),"Valid","Invalid") -> Valid | AI17: =IF(AND(F17>=0,F17<=2),"Valid","Invalid") -> Valid | AJ17: =IF(AND(G17>=0,G17<=2),"Valid","Invalid") -> Valid | AK17: =IF(AND(ISNUMBER(H17),H17>=DATE(2012,1,1),H17<=DATE(2014,12,31)),"Valid ","Invalid") -> Valid | AL17: =IF(AND(Audit_Data[[#This Row],[Recency]]>=0,Audit_Data[[#This Row],[Recency]]<=100),"Valid","Invalid") -> Valid | AM17: =IF(AND(ISNUMBER(J17),J17>=0,ISNUMBER(K17),K17>=0,ISNUMBER(L17),L17>=0,ISNUMBER(M17),M17>=0,ISNUMBER(N17),N17>=0,ISNUMBER(O17),O17>=0),"Valid","Invalid") -> Valid | AN17: =IF(AND(ISNUMBER(P17),P17>=0,ISNUMBER(Q17),Q17>=0,ISNUMBER(R17),R17>=0,ISNUMBER(S17),S17>=0,ISNUMBER(T17),T17>=0),"Valid","Invalid") -> Valid | AO17: =IF(AND(U17<=1,V17<=1,W17<=1,X17<=1,Y17<=1),"Valid","Invalid") -> Valid | AP17: =IF(OR(Z17=0,Z17=1),"Valid","Invalid") -> Valid | AQ17: =IF(Audit_Data[[#This Row],[Z_CostContact]]=3,"Valid","Invalid") -> Valid | AR17: =IF(AB17=11,"Valid","Invalid") -> Valid | AS17: =IF(OR(AC17=0,AC17=1),"Valid","Invalid") -> Valid
A18: 9736 | B18: 1980 | C18: Graduation | D18: Married | E18: 41850 | F18: 1 | G18: 1 | H18: 41267 | I18: 51 | J18: 53 | K18: 5 | L18: 19 | M18: 2 | N18: 13 | O18: 4 | P18: 3 | Q18: 3 | R18: 0 | S18: 3 | T18: 8 | U18: 0 | V18: 0 | W18: 0 | X18: 0 | Y18: 0 | Z18: 0 | AA18: 3 | AB18: 11 | AC18: 0 | AD18: =IF(COUNTIF(A:A,A18)>1,"Duplicate","Ok") -> Ok | AE18: =IF(AND(Audit_Data[[#This Row],[Year_Birth]]>=1900,Audit_Data[[#This Row],[Year_Birth]]<=2010),"OK","Invalid") -> OK | AF18: =IF(OR(C18="Graduation",C18="phD",C18="Master",C18="Basic",C18="2n Cycle"),"Valid","Invalid") -> Valid | AG18: =IF(OR(D18="Single",D18="Married",D18="Divorced",D18="Together",D18="Widow",D18="Alone"),"Valid","Invalid") -> Valid | AH18: =IF(AND(ISNUMBER(E18),E18<>""),"Valid","Invalid") -> Valid | AI18: =IF(AND(F18>=0,F18<=2),"Valid","Invalid") -> Valid | AJ18: =IF(AND(G18>=0,G18<=2),"Valid","Invalid") -> Valid | AK18: =IF(AND(ISNUMBER(H18),H18>=DATE(2012,1,1),H18<=DATE(2014,12,31)),"Valid ","Invalid") -> Valid | AL18: =IF(AND(Audit_Data[[#This Row],[Recency]]>=0,Audit_Data[[#This Row],[Recency]]<=100),"Valid","Invalid") -> Valid | AM18: =IF(AND(ISNUMBER(J18),J18>=0,ISNUMBER(K18),K18>=0,ISNUMBER(L18),L18>=0,ISNUMBER(M18),M18>=0,ISNUMBER(N18),N18>=0,ISNUMBER(O18),O18>=0),"Valid","Invalid") -> Valid | AN18: =IF(AND(ISNUMBER(P18),P18>=0,ISNUMBER(Q18),Q18>=0,ISNUMBER(R18),R18>=0,ISNUMBER(S18),S18>=0,ISNUMBER(T18),T18>=0),"Valid","Invalid") -> Valid | AO18: =IF(AND(U18<=1,V18<=1,W18<=1,X18<=1,Y18<=1),"Valid","Invalid") -> Valid | AP18: =IF(OR(Z18=0,Z18=1),"Valid","Invalid") -> Valid | AQ18: =IF(Audit_Data[[#This Row],[Z_CostContact]]=3,"Valid","Invalid") -> Valid | AR18: =IF(AB18=11,"Valid","Invalid") -> Valid | AS18: =IF(OR(AC18=0,AC18=1),"Valid","Invalid") -> Valid
A19: 4939 | B19: 1946 | C19: Graduation | D19: Together | E19: 37760 | F19: 0 | G19: 0 | H19: 41152 | I19: 20 | J19: 84 | K19: 5 | L19: 38 | M19: 150 | N19: 12 | O19: 28 | P19: 2 | Q19: 4 | R19: 1 | S19: 6 | T19: 7 | U19: 0 | V19: 0 | W19: 0 | X19: 0 | Y19: 0 | Z19: 0 | AA19: 3 | AB19: 11 | AC19: 0 | AD19: =IF(COUNTIF(A:A,A19)>1,"Duplicate","Ok") -> Ok | AE19: =IF(AND(Audit_Data[[#This Row],[Year_Birth]]>=1900,Audit_Data[[#This Row],[Year_Birth]]<=2010),"OK","Invalid") -> OK | AF19: =IF(OR(C19="Graduation",C19="phD",C19="Master",C19="Basic",C19="2n Cycle"),"Valid","Invalid") -> Valid | AG19: =IF(OR(D19="Single",D19="Married",D19="Divorced",D19="Together",D19="Widow",D19="Alone"),"Valid","Invalid") -> Valid | AH19: =IF(AND(ISNUMBER(E19),E19<>""),"Valid","Invalid") -> Valid | AI19: =IF(AND(F19>=0,F19<=2),"Valid","Invalid") -> Valid | AJ19: =IF(AND(G19>=0,G19<=2),"Valid","Invalid") -> Valid | AK19: =IF(AND(ISNUMBER(H19),H19>=DATE(2012,1,1),H19<=DATE(2014,12,31)),"Valid ","Invalid") -> Valid | AL19: =IF(AND(Audit_Data[[#This Row],[Recency]]>=0,Audit_Data[[#This Row],[Recency]]<=100),"Valid","Invalid") -> Valid | AM19: =IF(AND(ISNUMBER(J19),J19>=0,ISNUMBER(K19),K19>=0,ISNUMBER(L19),L19>=0,ISNUMBER(M19),M19>=0,ISNUMBER(N19),N19>=0,ISNUMBER(O19),O19>=0),"Valid","Invalid") -> Valid | AN19: =IF(AND(ISNUMBER(P19),P19>=0,ISNUMBER(Q19),Q19>=0,ISNUMBER(R19),R19>=0,ISNUMBER(S19),S19>=0,ISNUMBER(T19),T19>=0),"Valid","Invalid") -> Valid | AO19: =IF(AND(U19<=1,V19<=1,W19<=1,X19<=1,Y19<=1),"Valid","Invalid") -> Valid | AP19: =IF(OR(Z19=0,Z19=1),"Valid","Invalid") -> Valid | AQ19: =IF(Audit_Data[[#This Row],[Z_CostContact]]=3,"Valid","Invalid") -> Valid | AR19: =IF(AB19=11,"Valid","Invalid") -> Valid | AS19: =IF(OR(AC19=0,AC19=1),"Valid","Invalid") -> Valid
A20: 6565 | B20: 1949 | C20: Master | D20: Married | E20: 76995 | F20: 0 | G20: 1 | H20: 41361 | I20: 91 | J20: 1012 | K20: 80 | L20: 498 | M20: 0 | N20: 16 | O20: 176 | P20: 2 | Q20: 11 | R20: 4 | S20: 9 | T20: 5 | U20: 0 | V20: 0 | W20: 0 | X20: 1 | Y20: 0 | Z20: 0 | AA20: 3 | AB20: 11 | AC20: 0 | AD20: =IF(COUNTIF(A:A,A20)>1,"Duplicate","Ok") -> Ok | AE20: =IF(AND(Audit_Data[[#This Row],[Year_Birth]]>=1900,Audit_Data[[#This Row],[Year_Birth]]<=2010),"OK","Invalid") -> OK | AF20: =IF(OR(C20="Graduation",C20="phD",C20="Master",C20="Basic",C20="2n Cycle"),"Valid","Invalid") -> Valid | AG20: =IF(OR(D20="Single",D20="Married",D20="Divorced",D20="Together",D20="Widow",D20="Alone"),"Valid","Invalid") -> Valid | AH20: =IF(AND(ISNUMBER(E20),E20<>""),"Valid","Invalid") -> Valid | AI20: =IF(AND(F20>=0,F20<=2),"Valid","Invalid") -> Valid | AJ20: =IF(AND(G20>=0,G20<=2),"Valid","Invalid") -> Valid | AK20: =IF(AND(ISNUMBER(H20),H20>=DATE(2012,1,1),H20<=DATE(2014,12,31)),"Valid ","Invalid") -> Valid | AL20: =IF(AND(Audit_Data[[#This Row],[Recency]]>=0,Audit_Data[[#This Row],[Recency]]<=100),"Valid","Invalid") -> Valid | AM20: =IF(AND(ISNUMBER(J20),J20>=0,ISNUMBER(K20),K20>=0,ISNUMBER(L20),L20>=0,ISNUMBER(M20),M20>=0,ISNUMBER(N20),N20>=0,ISNUMBER(O20),O20>=0),"Valid","Invalid") -> Valid | AN20: =IF(AND(ISNUMBER(P20),P20>=0,ISNUMBER(Q20),Q20>=0,ISNUMBER(R20),R20>=0,ISNUMBER(S20),S20>=0,ISNUMBER(T20),T20>=0),"Valid","Invalid") -> Valid | AO20: =IF(AND(U20<=1,V20<=1,W20<=1,X20<=1,Y20<=1),"Valid","Invalid") -> Valid | AP20: =IF(OR(Z20=0,Z20=1),"Valid","Invalid") -> Valid | AQ20: =IF(Audit_Data[[#This Row],[Z_CostContact]]=3,"Valid","Invalid") -> Valid | AR20: =IF(AB20=11,"Valid","Invalid") -> Valid | AS20: =IF(OR(AC20=0,AC20=1),"Valid","Invalid") -> Valid
A21: 2278 | B21: 1985 | C21: 2n Cycle | D21: Single | E21: 33812 | F21: 1 | G21: 0 | H21: 41216 | I21: 86 | J21: 4 | K21: 17 | L21: 19 | M21: 30 | N21: 24 | O21: 39 | P21: 2 | Q21: 2 | R21: 1 | S21: 3 | T21: 6 | U21: 0 | V21: 0 | W21: 0 | X21: 0 | Y21: 0 | Z21: 0 | AA21: 3 | AB21: 11 | AC21: 0 | AD21: =IF(COUNTIF(A:A,A21)>1,"Duplicate","Ok") -> Ok | AE21: =IF(AND(Audit_Data[[#This Row],[Year_Birth]]>=1900,Audit_Data[[#This Row],[Year_Birth]]<=2010),"OK","Invalid") -> OK | AF21: =IF(OR(C21="Graduation",C21="phD",C21="Master",C21="Basic",C21="2n Cycle"),"Valid","Invalid") -> Valid | AG21: =IF(OR(D21="Single",D21="Married",D21="Divorced",D21="Together",D21="Widow",D21="Alone"),"Valid","Invalid") -> Valid | AH21: =IF(AND(ISNUMBER(E21),E21<>""),"Valid","Invalid") -> Valid | AI21: =IF(AND(F21>=0,F21<=2),"Valid","Invalid") -> Valid | AJ21: =IF(AND(G21>=0,G21<=2),"Valid","Invalid") -> Valid | AK21: =IF(AND(ISNUMBER(H21),H21>=DATE(2012,1,1),H21<=DATE(2014,12,31)),"Valid ","Invalid") -> Valid | AL21: =IF(AND(Audit_Data[[#This Row],[Recency]]>=0,Audit_Data[[#This Row],[Recency]]<=100),"Valid","Invalid") -> Valid | AM21: =IF(AND(ISNUMBER(J21),J21>=0,ISNUMBER(K21),K21>=0,ISNUMBER(L21),L21>=0,ISNUMBER(M21),M21>=0,ISNUMBER(N21),N21>=0,ISNUMBER(O21),O21>=0),"Valid","Invalid") -> Valid | AN21: =IF(AND(ISNUMBER(P21),P21>=0,ISNUMBER(Q21),Q21>=0,ISNUMBER(R21),R21>=0,ISNUMBER(S21),S21>=0,ISNUMBER(T21),T21>=0),"Valid","Invalid") -> Valid | AO21: =IF(AND(U21<=1,V21<=1,W21<=1,X21<=1,Y21<=1),"Valid","Invalid") -> Valid | AP21: =IF(OR(Z21=0,Z21=1),"Valid","Invalid") -> Valid | AQ21: =IF(Audit_Data[[#This Row],[Z_CostContact]]=3,"Valid","Invalid") -> Valid | AR21: =IF(AB21=11,"Valid","Invalid") -> Valid | AS21: =IF(OR(AC21=0,AC21=1),"Valid","Invalid") -> Valid
A22: 9360 | B22: 1982 | C22: Graduation | D22: Married | E22: 37040 | F22: 0 | G22: 0 | H22: 41129 | I22: 41 | J22: 86 | K22: 2 | L22: 73 | M22: 69 | N22: 38 | O22: 48 | P22: 1 | Q22: 4 | R22: 2 | S22: 5 | T22: 8 | U22: 0 | V22: 0 | W22: 0 | X22: 0 | Y22: 0 | Z22: 0 | AA22: 3 | AB22: 11 | AC22: 0 | AD22: =IF(COUNTIF(A:A,A22)>1,"Duplicate","Ok") -> Ok | AE22: =IF(AND(Audit_Data[[#This Row],[Year_Birth]]>=1900,Audit_Data[[#This Row],[Year_Birth]]<=2010),"OK","Invalid") -> OK | AF22: =IF(OR(C22="Graduation",C22="phD",C22="Master",C22="Basic",C22="2n Cycle"),"Valid","Invalid") -> Valid | AG22: =IF(OR(D22="Single",D22="Married",D22="Divorced",D22="Together",D22="Widow",D22="Alone"),"Valid","Invalid") -> Valid | AH22: =IF(AND(ISNUMBER(E22),E22<>""),"Valid","Invalid") -> Valid | AI22: =IF(AND(F22>=0,F22<=2),"Valid","Invalid") -> Valid | AJ22: =IF(AND(G22>=0,G22<=2),"Valid","Invalid") -> Valid | AK22: =IF(AND(ISNUMBER(H22),H22>=DATE(2012,1,1),H22<=DATE(2014,12,31)),"Valid ","Invalid") -> Valid | AL22: =IF(AND(Audit_Data[[#This Row],[Recency]]>=0,Audit_Data[[#This Row],[Recency]]<=100),"Valid","Invalid") -> Valid | AM22: =IF(AND(ISNUMBER(J22),J22>=0,ISNUMBER(K22),K22>=0,ISNUMBER(L22),L22>=0,ISNUMBER(M22),M22>=0,ISNUMBER(N22),N22>=0,ISNUMBER(O22),O22>=0),"Valid","Invalid") -> Valid | AN22: =IF(AND(ISNUMBER(P22),P22>=0,ISNUMBER(Q22),Q22>=0,ISNUMBER(R22),R22>=0,ISNUMBER(S22),S22>=0,ISNUMBER(T22),T22>=0),"Valid","Invalid") -> Valid | AO22: =IF(AND(U22<=1,V22<=1,W22<=1,X22<=1,Y22<=1),"Valid","Invalid") -> Valid | AP22: =IF(OR(Z22=0,Z22=1),"Valid","Invalid") -> Valid | AQ22: =IF(Audit_Data[[#This Row],[Z_CostContact]]=3,"Valid","Invalid") -> Valid | AR22: =IF(AB22=11,"Valid","Invalid") -> Valid | AS22: =IF(OR(AC22=0,AC22=1),"Valid","Invalid") -> Valid
A23: 5376 | B23: 1979 | C23: Graduation | D23: Married | E23: 2447 | F23: 1 | G23: 0 | H23: 41280 | I23: 42 | J23: 1 | K23: 1 | L23: 1725 | M23: 1 | N23: 1 | O23: 1 | P23: 15 | Q23: 0 | R23: 28 | S23: 0 | T23: 1 | U23: 0 | V23: 0 | W23: 0 | X23: 0 | Y23: 0 | Z23: 0 | AA23: 3 | AB23: 11 | AC23: 0 | AD23: =IF(COUNTIF(A:A,A23)>1,"Duplicate","Ok") -> Ok | AE23: =IF(AND(Audit_Data[[#This Row],[Year_Birth]]>=1900,Audit_Data[[#This Row],[Year_Birth]]<=2010),"OK","Invalid") -> OK | AF23: =IF(OR(C23="Graduation",C23="phD",C23="Master",C23="Basic",C23="2n Cycle"),"Valid","Invalid") -> Valid | AG23: =IF(OR(D23="Single",D23="Married",D23="Divorced",D23="Together",D23="Widow",D23="Alone"),"Valid","Invalid") -> Valid | AH23: =IF(AND(ISNUMBER(E23),E23<>""),"Valid","Invalid") -> Valid | AI23: =IF(AND(F23>=0,F23<=2),"Valid","Invalid") -> Valid | AJ23: =IF(AND(G23>=0,G23<=2),"Valid","Invalid") -> Valid | AK23: =IF(AND(ISNUMBER(H23),H23>=DATE(2012,1,1),H23<=DATE(2014,12,31)),"Valid ","Invalid") -> Valid | AL23: =IF(AND(Audit_Data[[#This Row],[Recency]]>=0,Audit_Data[[#This Row],[Recency]]<=100),"Valid","Invalid") -> Valid | AM23: =IF(AND(ISNUMBER(J23),J23>=0,ISNUMBER(K23),K23>=0,ISNUMBER(L23),L23>=0,ISNUMBER(M23),M23>=0,ISNUMBER(N23),N23>=0,ISNUMBER(O23),O23>=0),"Valid","Invalid") -> Valid | AN23: =IF(AND(ISNUMBER(P23),P23>=0,ISNUMBER(Q23),Q23>=0,ISNUMBER(R23),R23>=0,ISNUMBER(S23),S23>=0,ISNUMBER(T23),T23>=0),"Valid","Invalid") -> Valid | AO23: =IF(AND(U23<=1,V23<=1,W23<=1,X23<=1,Y23<=1),"Valid","Invalid") -> Valid | AP23: =IF(OR(Z23=0,Z23=1),"Valid","Invalid") -> Valid | AQ23: =IF(Audit_Data[[#This Row],[Z_CostContact]]=3,"Valid","Invalid") -> Valid | AR23: =IF(AB23=11,"Valid","Invalid") -> Valid | AS23: =IF(OR(AC23=0,AC23=1),"Valid","Invalid") -> Valid
A24: 1993 | B24: 1949 | C24: PhD | D24: Married | E24: 58607 | F24: 0 | G24: 1 | H24: 41266 | I24: 63 | J24: 867 | K24: 0 | L24: 86 | M24: 0 | N24: 0 | O24: 19 | P24: 3 | Q24: 2 | R24: 3 | S24: 9 | T24: 8 | U24: 0 | V24: 1 | W24: 0 | X24: 0 | Y24: 0 | Z24: 0 | AA24: 3 | AB24: 11 | AC24: 0 | AD24: =IF(COUNTIF(A:A,A24)>1,"Duplicate","Ok") -> Ok | AE24: =IF(AND(Audit_Data[[#This Row],[Year_Birth]]>=1900,Audit_Data[[#This Row],[Year_Birth]]<=2010),"OK","Invalid") -> OK | AF24: =IF(OR(C24="Graduation",C24="phD",C24="Master",C24="Basic",C24="2n Cycle"),"Valid","Invalid") -> Valid | AG24: =IF(OR(D24="Single",D24="Married",D24="Divorced",D24="Together",D24="Widow",D24="Alone"),"Valid","Invalid") -> Valid | AH24: =IF(AND(ISNUMBER(E24),E24<>""),"Valid","Invalid") -> Valid | AI24: =IF(AND(F24>=0,F24<=2),"Valid","Invalid") -> Valid | AJ24: =IF(AND(G24>=0,G24<=2),"Valid","Invalid") -> Valid | AK24: =IF(AND(ISNUMBER(H24),H24>=DATE(2012,1,1),H24<=DATE(2014,12,31)),"Valid ","Invalid") -> Valid | AL24: =IF(AND(Audit_Data[[#This Row],[Recency]]>=0,Audit_Data[[#This Row],[Recency]]<=100),"Valid","Invalid") -> Valid | AM24: =IF(AND(ISNUMBER(J24),J24>=0,ISNUMBER(K24),K24>=0,ISNUMBER(L24),L24>=0,ISNUMBER(M24),M24>=0,ISNUMBER(N24),N24>=0,ISNUMBER(O24),O24>=0),"Valid","Invalid") -> Valid | AN24: =IF(AND(ISNUMBER(P24),P24>=0,ISNUMBER(Q24),Q24>=0,ISNUMBER(R24),R24>=0,ISNUMBER(S24),S24>=0,ISNUMBER(T24),T24>=0),"Valid","Invalid") -> Valid | AO24: =IF(AND(U24<=1,V24<=1,W24<=1,X24<=1,Y24<=1),"Valid","Invalid") -> Valid | AP24: =IF(OR(Z24=0,Z24=1),"Valid","Invalid") -> Valid | AQ24: =IF(Audit_Data[[#This Row],[Z_CostContact]]=3,"Valid","Invalid") -> Valid | AR24: =IF(AB24=11,"Valid","Invalid") -> Valid | AS24: =IF(OR(AC24=0,AC24=1),"Valid","Invalid") -> Valid
... A28: 2404 | B28: 1976 | C28: Graduation | D28: Married | E28: 53359 | F28: 1 | G28: 1 | H28: 41421 | I28: 4 | J28: 173 | K28: 4 | L28: 30 | M28: 3 | N28: 6 | O28: 41 | P28: 4 | Q28: 5 | R28: 1 | S28: 4 | T28: 7 | U28: 0 | V28: 0 | W28: 0 | X28: 0 | Y28: 0 | Z28: 0 | AA28: 3 | AB28: 11 | AC28: 0 | AD28: =IF(COUNTIF(A:A,A28)>1,"Duplicate","Ok") -> Ok | AE28: =IF(AND(Audit_Data[[#This Row],[Year_Birth]]>=1900,Audit_Data[[#This Row],[Year_Birth]]<=2010),"OK","Invalid") -> OK | AF28: =IF(OR(C28="Graduation",C28="phD",C28="Master",C28="Basic",C28="2n Cycle"),"Valid","Invalid") -> Valid | AG28: =IF(OR(D28="Single",D28="Married",D28="Divorced",D28="Together",D28="Widow",D28="Alone"),"Valid","Invalid") -> Valid | AH28: =IF(AND(ISNUMBER(E28),E28<>""),"Valid","Invalid") -> Valid | AI28: =IF(AND(F28>=0,F28<=2),"Valid","Invalid") -> Valid | AJ28: =IF(AND(G28>=0,G28<=2),"Valid","Invalid") -> Valid | AK28: =IF(AND(ISNUMBER(H28),H28>=DATE(2012,1,1),H28<=DATE(2014,12,31)),"Valid ","Invalid") -> Valid | AL28: =IF(AND(Audit_Data[[#This Row],[Recency]]>=0,Audit_Data[[#This Row],[Recency]]<=100),"Valid","Invalid") -> Valid | AM28: =IF(AND(ISNUMBER(J28),J28>=0,ISNUMBER(K28),K28>=0,ISNUMBER(L28),L28>=0,ISNUMBER(M28),M28>=0,ISNUMBER(N28),N28>=0,ISNUMBER(O28),O28>=0),"Valid","Invalid") -> Valid | AN28: =IF(AND(ISNUMBER(P28),P28>=0,ISNUMBER(Q28),Q28>=0,ISNUMBER(R28),R28>=0,ISNUMBER(S28),S28>=0,ISNUMBER(T28),T28>=0),"Valid","Invalid") -> Valid | AO28: =IF(AND(U28<=1,V28<=1,W28<=1,X28<=1,Y28<=1),"Valid","Invalid") -> Valid | AP28: =IF(OR(Z28=0,Z28=1),"Valid","Invalid") -> Valid | AQ28: =IF(Audit_Data[[#This Row],[Z_CostContact]]=3,"Valid","Invalid") -> Valid | AR28: =IF(AB28=11,"Valid","Invalid") -> Valid | AS28: =IF(OR(AC28=0,AC28=1),"Valid","Invalid") -> Valid
A29: 5255 | B29: 1986 | C29: Graduation | D29: Single | F29: 1 | G29: 0 | H29: 41325 | I29: 19 | J29: 5 | K29: 1 | L29: 3 | M29: 3 | N29: 263 | O29: 362 | P29: 0 | Q29: 27 | R29: 0 | S29: 0 | T29: 1 | U29: 0 | V29: 0 | W29: 0 | X29: 0 | Y29: 0 | Z29: 0 | AA29: 3 | AB29: 11 | AC29: 0 | AD29: =IF(COUNTIF(A:A,A29)>1,"Duplicate","Ok") -> Ok | AE29: =IF(AND(Audit_Data[[#This Row],[Year_Birth]]>=1900,Audit_Data[[#This Row],[Year_Birth]]<=2010),"OK","Invalid") -> OK | AF29: =IF(OR(C29="Graduation",C29="phD",C29="Master",C29="Basic",C29="2n Cycle"),"Valid","Invalid") -> Valid | AG29: =IF(OR(D29="Single",D29="Married",D29="Divorced",D29="Together",D29="Widow",D29="Alone"),"Valid","Invalid") -> Valid | AH29: =IF(AND(ISNUMBER(E29),E29<>""),"Valid","Invalid") -> Invalid | AI29: =IF(AND(F29>=0,F29<=2),"Valid","Invalid") -> Valid | AJ29: =IF(AND(G29>=0,G29<=2),"Valid","Invalid") -> Valid | AK29: =IF(AND(ISNUMBER(H29),H29>=DATE(2012,1,1),H29<=DATE(2014,12,31)),"Valid ","Invalid") -> Valid | AL29: =IF(AND(Audit_Data[[#This Row],[Recency]]>=0,Audit_Data[[#This Row],[Recency]]<=100),"Valid","Invalid") -> Valid | AM29: =IF(AND(ISNUMBER(J29),J29>=0,ISNUMBER(K29),K29>=0,ISNUMBER(L29),L29>=0,ISNUMBER(M29),M29>=0,ISNUMBER(N29),N29>=0,ISNUMBER(O29),O29>=0),"Valid","Invalid") -> Valid | AN29: =IF(AND(ISNUMBER(P29),P29>=0,ISNUMBER(Q29),Q29>=0,ISNUMBER(R29),R29>=0,ISNUMBER(S29),S29>=0,ISNUMBER(T29),T29>=0),"Valid","Invalid") -> Valid | AO29: =IF(AND(U29<=1,V29<=1,W29<=1,X29<=1,Y29<=1),"Valid","Invalid") -> Valid | AP29: =IF(OR(Z29=0,Z29=1),"Valid","Invalid") -> Valid | AQ29: =IF(Audit_Data[[#This Row],[Z_CostContact]]=3,"Valid","Invalid") -> Valid | AR29: =IF(AB29=11,"Valid","Invalid") -> Valid | AS29: =IF(OR(AC29=0,AC29=1),"Valid","Invalid") -> Valid
A30: 9422 | B30: 1989 | C30: Graduation | D30: Married | E30: 38360 | F30: 1 | G30: 0 | H30: 41425 | I30: 26 | J30: 36 | K30: 2 | L30: 42 | M30: 20 | N30: 21 | O30: 10 | P30: 2 | Q30: 2 | R30: 1 | S30: 4 | T30: 3 | U30: 0 | V30: 0 | W30: 0 | X30: 0 | Y30: 0 | Z30: 0 | AA30: 3 | AB30: 11 | AC30: 0 | AD30: =IF(COUNTIF(A:A,A30)>1,"Duplicate","Ok") -> Ok | AE30: =IF(AND(Audit_Data[[#This Row],[Year_Birth]]>=1900,Audit_Data[[#This Row],[Year_Birth]]<=2010),"OK","Invalid") -> OK | AF30: =IF(OR(C30="Graduation",C30="phD",C30="Master",C30="Basic",C30="2n Cycle"),"Valid","Invalid") -> Valid | AG30: =IF(OR(D30="Single",D30="Married",D30="Divorced",D30="Together",D30="Widow",D30="Alone"),"Valid","Invalid") -> Valid | AH30: =IF(AND(ISNUMBER(E30),E30<>""),"Valid","Invalid") -> Valid | AI30: =IF(AND(F30>=0,F30<=2),"Valid","Invalid") -> Valid | AJ30: =IF(AND(G30>=0,G30<=2),"Valid","Invalid") -> Valid | AK30: =IF(AND(ISNUMBER(H30),H30>=DATE(2012,1,1),H30<=DATE(2014,12,31)),"Valid ","Invalid") -> Valid | AL30: =IF(AND(Audit_Data[[#This Row],[Recency]]>=0,Audit_Data[[#This Row],[Recency]]<=100),"Valid","Invalid") -> Valid | AM30: =IF(AND(ISNUMBER(J30),J30>=0,ISNUMBER(K30),K30>=0,ISNUMBER(L30),L30>=0,ISNUMBER(M30),M30>=0,ISNUMBER(N30),N30>=0,ISNUMBER(O30),O30>=0),"Valid","Invalid") -> Valid | AN30: =IF(AND(ISNUMBER(P30),P30>=0,ISNUMBER(Q30),Q30>=0,ISNUMBER(R30),R30>=0,ISNUMBER(S30),S30>=0,ISNUMBER(T30),T30>=0),"Valid","Invalid") -> Valid | AO30: =IF(AND(U30<=1,V30<=1,W30<=1,X30<=1,Y30<=1),"Valid","Invalid") -> Valid | AP30: =IF(OR(Z30=0,Z30=1),"Valid","Invalid") -> Valid | AQ30: =IF(Audit_Data[[#This Row],[Z_CostContact]]=3,"Valid","Invalid") -> Valid | AR30: =IF(AB30=11,"Valid","Invalid") -> Valid | AS30: =IF(OR(AC30=0,AC30=1),"Valid","Invalid") -> Valid
A31: 1966 | B31: 1965 | C31: PhD | D31: Married | E31: 84618 | F31: 0 | G31: 0 | H31: 41600 | I31: 96 | J31: 684 | K31: 100 | L31: 801 | M31: 21 | N31: 66 | O31: 0 | P31: 1 | Q31: 6 | R31: 9 | S31: 10 | T31: 2 | U31: 0 | V31: 0 | W31: 1 | X31: 0 | Y31: 0 | Z31: 0 | AA31: 3 | AB31: 11 | AC31: 0 | AD31: =IF(COUNTIF(A:A,A31)>1,"Duplicate","Ok") -> Ok | AE31: =IF(AND(Audit_Data[[#This Row],[Year_Birth]]>=1900,Audit_Data[[#This Row],[Year_Birth]]<=2010),"OK","Invalid") -> OK | AF31: =IF(OR(C31="Graduation",C31="phD",C31="Master",C31="Basic",C31="2n Cycle"),"Valid","Invalid") -> Valid | AG31: =IF(OR(D31="Single",D31="Married",D31="Divorced",D31="Together",D31="Widow",D31="Alone"),"Valid","Invalid") -> Valid | AH31: =IF(AND(ISNUMBER(E31),E31<>""),"Valid","Invalid") -> Valid | AI31: =IF(AND(F31>=0,F31<=2),"Valid","Invalid") -> Valid | AJ31: =IF(AND(G31>=0,G31<=2),"Valid","Invalid") -> Valid | AK31: =IF(AND(ISNUMBER(H31),H31>=DATE(2012,1,1),H31<=DATE(2014,12,31)),"Valid ","Invalid") -> Valid | AL31: =IF(AND(Audit_Data[[#This Row],[Recency]]>=0,Audit_Data[[#This Row],[Recency]]<=100),"Valid","Invalid") -> Valid | AM31: =IF(AND(ISNUMBER(J31),J31>=0,ISNUMBER(K31),K31>=0,ISNUMBER(L31),L31>=0,ISNUMBER(M31),M31>=0,ISNUMBER(N31),N31>=0,ISNUMBER(O31),O31>=0),"Valid","Invalid") -> Valid | AN31: =IF(AND(ISNUMBER(P31),P31>=0,ISNUMBER(Q31),Q31>=0,ISNUMBER(R31),R31>=0,ISNUMBER(S31),S31>=0,ISNUMBER(T31),T31>=0),"Valid","Invalid") -> Valid | AO31: =IF(AND(U31<=1,V31<=1,W31<=1,X31<=1,Y31<=1),"Valid","Invalid") -> Valid | AP31: =IF(OR(Z31=0,Z31=1),"Valid","Invalid") -> Valid | AQ31: =IF(Audit_Data[[#This Row],[Z_CostContact]]=3,"Valid","Invalid") -> Valid | AR31: =IF(AB31=11,"Valid","Invalid") -> Valid | AS31: =IF(OR(AC31=0,AC31=1),"Valid","Invalid") -> Valid
A32: 6864 | B32: 1989 | C32: Master | D32: Divorced | E32: 10979 | F32: 0 | G32: 0 | H32: 41781 | I32: 34 | J32: 8 | K32: 4 | L32: 10 | M32: 2 | N32: 2 | O32: 4 | P32: 2 | Q32: 3 | R32: 0 | S32: 3 | T32: 5 | U32: 0 | V32: 0 | W32: 0 | X32: 0 | Y32: 0 | Z32: 0 | AA32: 3 | AB32: 11 | AC32: 0 | AD32: =IF(COUNTIF(A:A,A32)>1,"Duplicate","Ok") -> Ok | AE32: =IF(AND(Audit_Data[[#This Row],[Year_Birth]]>=1900,Audit_Data[[#This Row],[Year_Birth]]<=2010),"OK","Invalid") -> OK | AF32: =IF(OR(C32="Graduation",C32="phD",C32="Master",C32="Basic",C32="2n Cycle"),"Valid","Invalid") -> Valid | AG32: =IF(OR(D32="Single",D32="Married",D32="Divorced",D32="Together",D32="Widow",D32="Alone"),"Valid","Invalid") -> Valid | AH32: =IF(AND(ISNUMBER(E32),E32<>""),"Valid","Invalid") -> Valid | AI32: =IF(AND(F32>=0,F32<=2),"Valid","Invalid") -> Valid | AJ32: =IF(AND(G32>=0,G32<=2),"Valid","Invalid") -> Valid | AK32: =IF(AND(ISNUMBER(H32),H32>=DATE(2012,1,1),H32<=DATE(2014,12,31)),"Valid ","Invalid") -> Valid | AL32: =IF(AND(Audit_Data[[#This Row],[Recency]]>=0,Audit_Data[[#This Row],[Recency]]<=100),"Valid","Invalid") -> Valid | AM32: =IF(AND(ISNUMBER(J32),J32>=0,ISNUMBER(K32),K32>=0,ISNUMBER(L32),L32>=0,ISNUMBER(M32),M32>=0,ISNUMBER(N32),N32>=0,ISNUMBER(O32),O32>=0),"Valid","Invalid") -> Valid | AN32: =IF(AND(ISNUMBER(P32),P32>=0,ISNUMBER(Q32),Q32>=0,ISNUMBER(R32),R32>=0,ISNUMBER(S32),S32>=0,ISNUMBER(T32),T32>=0),"Valid","Invalid") -> Valid | AO32: =IF(AND(U32<=1,V32<=1,W32<=1,X32<=1,Y32<=1),"Valid","Invalid") -> Valid | AP32: =IF(OR(Z32=0,Z32=1),"Valid","Invalid") -> Valid | AQ32: =IF(Audit_Data[[#This Row],[Z_CostContact]]=3,"Valid","Invalid") -> Valid | AR32: =IF(AB32=11,"Valid","Invalid") -> Valid | AS32: =IF(OR(AC32=0,AC32=1),"Valid","Invalid") -> Valid
A33: 3033 | B33: 1963 | C33: Master | D33: Together | E33: 38620 | F33: 0 | G33: 0 | H33: 41405 | I33: 56 | J33: 112 | K33: 17 | L33: 44 | M33: 34 | N33: 22 | O33: 89 | P33: 1 | Q33: 2 | R33: 5 | S33: 3 | T33: 3 | U33: 0 | V33: 0 | W33: 0 | X33: 0 | Y33: 0 | Z33: 0 | AA33: 3 | AB33: 11 | AC33: 0 | AD33: =IF(COUNTIF(A:A,A33)>1,"Duplicate","Ok") -> Ok | AE33: =IF(AND(Audit_Data[[#This Row],[Year_Birth]]>=1900,Audit_Data[[#This Row],[Year_Birth]]<=2010),"OK","Invalid") -> OK | AF33: =IF(OR(C33="Graduation",C33="phD",C33="Master",C33="Basic",C33="2n Cycle"),"Valid","Invalid") -> Valid | AG33: =IF(OR(D33="Single",D33="Married",D33="Divorced",D33="Together",D33="Widow",D33="Alone"),"Valid","Invalid") -> Valid | AH33: =IF(AND(ISNUMBER(E33),E33<>""),"Valid","Invalid") -> Valid | AI33: =IF(AND(F33>=0,F33<=2),"Valid","Invalid") -> Valid | AJ33: =IF(AND(G33>=0,G33<=2),"Valid","Invalid") -> Valid | AK33: =IF(AND(ISNUMBER(H33),H33>=DATE(2012,1,1),H33<=DATE(2014,12,31)),"Valid ","Invalid") -> Valid | AL33: =IF(AND(Audit_Data[[#This Row],[Recency]]>=0,Audit_Data[[#This Row],[Recency]]<=100),"Valid","Invalid") -> Valid | AM33: =IF(AND(ISNUMBER(J33),J33>=0,ISNUMBER(K33),K33>=0,ISNUMBER(L33),L33>=0,ISNUMBER(M33),M33>=0,ISNUMBER(N33),N33>=0,ISNUMBER(O33),O33>=0),"Valid","Invalid") -> Valid | AN33: =IF(AND(ISNUMBER(P33),P33>=0,ISNUMBER(Q33),Q33>=0,ISNUMBER(R33),R33>=0,ISNUMBER(S33),S33>=0,ISNUMBER(T33),T33>=0),"Valid","Invalid") -> Valid | AO33: =IF(AND(U33<=1,V33<=1,W33<=1,X33<=1,Y33<=1),"Valid","Invalid") -> Valid | AP33: =IF(OR(Z33=0,Z33=1),"Valid","Invalid") -> Valid | AQ33: =IF(Audit_Data[[#This Row],[Z_CostContact]]=3,"Valid","Invalid") -> Valid | AR33: =IF(AB33=11,"Valid","Invalid") -> Valid | AS33: =IF(OR(AC33=0,AC33=1),"Valid","Invalid") -> Valid
A34: 5710 | B34: 1970 | C34: Graduation | D34: Together | E34: 40548 | F34: 0 | G34: 1 | H34: 41192 | I34: 31 | J34: 110 | K34: 0 | L34: 5 | M34: 2 | N34: 0 | O34: 3 | P34: 2 | Q34: 2 | R34: 1 | S34: 4 | T34: 5 | U34: 0 | V34: 1 | W34: 0 | X34: 0 | Y34: 0 | Z34: 0 | AA34: 3 | AB34: 11 | AC34: 0 | AD34: =IF(COUNTIF(A:A,A34)>1,"Duplicate","Ok") -> Ok | AE34: =IF(AND(Audit_Data[[#This Row],[Year_Birth]]>=1900,Audit_Data[[#This Row],[Year_Birth]]<=2010),"OK","Invalid") -> OK | AF34: =IF(OR(C34="Graduation",C34="phD",C34="Master",C34="Basic",C34="2n Cycle"),"Valid","Invalid") -> Valid | AG34: =IF(OR(D34="Single",D34="Married",D34="Divorced",D34="Together",D34="Widow",D34="Alone"),"Valid","Invalid") -> Valid | AH34: =IF(AND(ISNUMBER(E34),E34<>""),"Valid","Invalid") -> Valid | AI34: =IF(AND(F34>=0,F34<=2),"Valid","Invalid") -> Valid | AJ34: =IF(AND(G34>=0,G34<=2),"Valid","Invalid") -> Valid | AK34: =IF(AND(ISNUMBER(H34),H34>=DATE(2012,1,1),H34<=DATE(2014,12,31)),"Valid ","Invalid") -> Valid | AL34: =IF(AND(Audit_Data[[#This Row],[Recency]]>=0,Audit_Data[[#This Row],[Recency]]<=100),"Valid","Invalid") -> Valid | AM34: =IF(AND(ISNUMBER(J34),J34>=0,ISNUMBER(K34),K34>=0,ISNUMBER(L34),L34>=0,ISNUMBER(M34),M34>=0,ISNUMBER(N34),N34>=0,ISNUMBER(O34),O34>=0),"Valid","Invalid") -> Valid | AN34: =IF(AND(ISNUMBER(P34),P34>=0,ISNUMBER(Q34),Q34>=0,ISNUMBER(R34),R34>=0,ISNUMBER(S34),S34>=0,ISNUMBER(T34),T34>=0),"Valid","Invalid") -> Valid | AO34: =IF(AND(U34<=1,V34<=1,W34<=1,X34<=1,Y34<=1),"Valid","Invalid") -> Valid | AP34: =IF(OR(Z34=0,Z34=1),"Valid","Invalid") -> Valid | AQ34: =IF(Audit_Data[[#This Row],[Z_CostContact]]=3,"Valid","Invalid") -> Valid | AR34: =IF(AB34=11,"Valid","Invalid") -> Valid | AS34: =IF(OR(AC34=0,AC34=1),"Valid","Invalid") -> Valid
A35: 7373 | B35: 1952 | C35: PhD | D35: Divorced | E35: 46610 | F35: 0 | G35: 2 | H35: 41211 | I35: 8 | J35: 96 | K35: 12 | L35: 96 | M35: 33 | N35: 22 | O35: 43 | P35: 6 | Q35: 4 | R35: 1 | S35: 6 | T35: 6 | U35: 0 | V35: 0 | W35: 0 | X35: 0 | Y35: 0 | Z35: 0 | AA35: 3 | AB35: 11 | AC35: 1 | AD35: =IF(COUNTIF(A:A,A35)>1,"Duplicate","Ok") -> Ok | AE35: =IF(AND(Audit_Data[[#This Row],[Year_Birth]]>=1900,Audit_Data[[#This Row],[Year_Birth]]<=2010),"OK","Invalid") -> OK | AF35: =IF(OR(C35="Graduation",C35="phD",C35="Master",C35="Basic",C35="2n Cycle"),"Valid","Invalid") -> Valid | AG35: =IF(OR(D35="Single",D35="Married",D35="Divorced",D35="Together",D35="Widow",D35="Alone"),"Valid","Invalid") -> Valid | AH35: =IF(AND(ISNUMBER(E35),E35<>""),"Valid","Invalid") -> Valid | AI35: =IF(AND(F35>=0,F35<=2),"Valid","Invalid") -> Valid | AJ35: =IF(AND(G35>=0,G35<=2),"Valid","Invalid") -> Valid | AK35: =IF(AND(ISNUMBER(H35),H35>=DATE(2012,1,1),H35<=DATE(2014,12,31)),"Valid ","Invalid") -> Valid | AL35: =IF(AND(Audit_Data[[#This Row],[Recency]]>=0,Audit_Data[[#This Row],[Recency]]<=100),"Valid","Invalid") -> Valid | AM35: =IF(AND(ISNUMBER(J35),J35>=0,ISNUMBER(K35),K35>=0,ISNUMBER(L35),L35>=0,ISNUMBER(M35),M35>=0,ISNUMBER(N35),N35>=0,ISNUMBER(O35),O35>=0),"Valid","Invalid") -> Valid | AN35: =IF(AND(ISNUMBER(P35),P35>=0,ISNUMBER(Q35),Q35>=0,ISNUMBER(R35),R35>=0,ISNUMBER(S35),S35>=0,ISNUMBER(T35),T35>=0),"Valid","Invalid") -> Valid | AO35: =IF(AND(U35<=1,V35<=1,W35<=1,X35<=1,Y35<=1),"Valid","Invalid") -> Valid | AP35: =IF(OR(Z35=0,Z35=1),"Valid","Invalid") -> Valid | AQ35: =IF(Audit_Data[[#This Row],[Z_CostContact]]=3,"Valid","Invalid") -> Valid | AR35: =IF(AB35=11,"Valid","Invalid") -> Valid | AS35: =IF(OR(AC35=0,AC35=1),"Valid","Invalid") -> Valid
A36: 8755 | B36: 1946 | C36: Master | D36: Married | E36: 68657 | F36: 0 | G36: 0 | H36: 41325 | I36: 4 | J36: 482 | K36: 34 | L36: 471 | M36: 119 | N36: 68 | O36: 22 | P36: 1 | Q36: 3 | R36: 5 | S36: 9 | T36: 7 | U36: 0 | V36: 0 | W36: 0 | X36: 0 | Y36: 0 | Z36: 0 | AA36: 3 | AB36: 11 | AC36: 0 | AD36: =IF(COUNTIF(A:A,A36)>1,"Duplicate","Ok") -> Ok | AE36: =IF(AND(Audit_Data[[#This Row],[Year_Birth]]>=1900,Audit_Data[[#This Row],[Year_Birth]]<=2010),"OK","Invalid") -> OK | AF36: =IF(OR(C36="Graduation",C36="phD",C36="Master",C36="Basic",C36="2n Cycle"),"Valid","Invalid") -> Valid | AG36: =IF(OR(D36="Single",D36="Married",D36="Divorced",D36="Together",D36="Widow",D36="Alone"),"Valid","Invalid") -> Valid | AH36: =IF(AND(ISNUMBER(E36),E36<>""),"Valid","Invalid") -> Valid | AI36: =IF(AND(F36>=0,F36<=2),"Valid","Invalid") -> Valid | AJ36: =IF(AND(G36>=0,G36<=2),"Valid","Invalid") -> Valid | AK36: =IF(AND(ISNUMBER(H36),H36>=DATE(2012,1,1),H36<=DATE(2014,12,31)),"Valid ","Invalid") -> Valid | AL36: =IF(AND(Audit_Data[[#This Row],[Recency]]>=0,Audit_Data[[#This Row],[Recency]]<=100),"Valid","Invalid") -> Valid | AM36: =IF(AND(ISNUMBER(J36),J36>=0,ISNUMBER(K36),K36>=0,ISNUMBER(L36),L36>=0,ISNUMBER(M36),M36>=0,ISNUMBER(N36),N36>=0,ISNUMBER(O36),O36>=0),"Valid","Invalid") -> Valid | AN36: =IF(AND(ISNUMBER(P36),P36>=0,ISNUMBER(Q36),Q36>=0,ISNUMBER(R36),R36>=0,ISNUMBER(S36),S36>=0,ISNUMBER(T36),T36>=0),"Valid","Invalid") -> Valid | AO36: =IF(AND(U36<=1,V36<=1,W36<=1,X36<=1,Y36<=1),"Valid","Invalid") -> Valid | AP36: =IF(OR(Z36=0,Z36=1),"Valid","Invalid") -> Valid | AQ36: =IF(Audit_Data[[#This Row],[Z_CostContact]]=3,"Valid","Invalid") -> Valid | AR36: =IF(AB36=11,"Valid","Invalid") -> Valid | AS36: =IF(OR(AC36=0,AC36=1),"Valid","Invalid") -> Valid
